concurrent.futures.process._RemoteTraceback: 
"""
Traceback (most recent call last):
  File "/home/home01/sclaam/.conda/envs/GraphNetworks/lib/python3.9/concurrent/futures/process.py", line 243, in _process_worker
    r = call_item.fn(*call_item.args, **call_item.kwargs)
  File "/home/home01/sclaam/CombOpt_ML/struc2vec/src/algorithms_distances.py", line 442, in exec_bfs
    chunks = partition(vertices,parts)
  File "/home/home01/sclaam/CombOpt_ML/struc2vec/src/utils.py", line 24, in partition
    return [ lst[int(round(division * i)): int(round(division * (i + 1)))] for i in xrange(n) ]
NameError: name 'xrange' is not defined
"""

The above exception was the direct cause of the following exception:

Traceback (most recent call last):
  File "/home/home01/sclaam/CombOpt_ML/struc2vec/src/main.py", line 128, in <module>
    main(args)
  File "/home/home01/sclaam/CombOpt_ML/struc2vec/src/main.py", line 121, in main
    G = exec_struc2vec(args)
  File "/home/home01/sclaam/CombOpt_ML/struc2vec/src/main.py", line 102, in exec_struc2vec
    G.preprocess_neighbors_with_bfs()
  File "/home/home01/sclaam/CombOpt_ML/struc2vec/src/struc2vec.py", line 37, in preprocess_neighbors_with_bfs
    job.result()
  File "/home/home01/sclaam/.conda/envs/GraphNetworks/lib/python3.9/concurrent/futures/_base.py", line 446, in result
    return self.__get_result()
  File "/home/home01/sclaam/.conda/envs/GraphNetworks/lib/python3.9/concurrent/futures/_base.py", line 391, in __get_result
    raise self._exception
NameError: name 'xrange' is not defined
